Workbook

Sheet Pivot
A1: Trạng thái dự án | B1: (Multiple Items)
A2: Tên dự án | B2: (All)
A3: Trạng thái nhân viên | B3: (All)
A5: Phòng | B5: Họ và Tên | C5: Sum of 1/5/2026 | D5: Sum of 1/12/2026 | E5: Sum of 1/19/2026 | F5: Sum of 1/26/2026 | G5: Sum of 2/2/2026 | H5: Sum of 2/9/2026 | I5: Sum of 2/16/2026 | J5: Sum of 2/23/2026 | K5: Sum of 3/2/2026 | L5: Sum of 3/9/2026 | M5: Sum of 3/16/2026 | N5: Sum of 3/23/2026 | O5: Sum of 3/30/2026 | P5: Sum of 4/6/2026 | Q5: Sum of 4/13/2026 | R5: Sum of 4/20/2026 | S5: Sum of 4/27/2026 | T5: Sum of 5/4/2026 | U5: Sum of 5/11/2026 | V5: Sum of 5/18/2026 | W5: Sum of 5/25/2026 | X5: Sum of 6/1/2026 | Y5: Sum of 6/8/2026 | Z5: Sum of 6/15/2026 | AA5: Sum of 6/22/2026 | AB5: Sum of 6/29/2026
A6: P.Kỹ thuật IBS | B6: Đỗ Trung Hiếu | C6: 1 | D6: 1 | E6: 1 | F6: 1 | G6: 1 | H6: 1 | J6: 0.5 | K6: 1 | L6: 1 | M6: 1 | N6: 1 | O6: 1 | P6: 1 | Q6: 1 | R6: 1 | S6: 1 | T6: 1 | U6: 1 | V6: 1 | W6: 1 | X6: 1 | Y6: 1 | Z6: 1 | AA6: 1 | AB6: 1
B7: Lê Chí Công | C7: 0.95 | D7: 0.9 | E7: 1 | F7: 1 | G7: 1 | H7: 0.7 | J7: 0.7 | K7: 1 | L7: 1 | M7: 1 | N7: 1 | O7: 1 | P7: 1 | Q7: 1 | R7: 1 | S7: 1 | T7: 1 | U7: 1 | V7: 1 | W7: 1 | X7: 1 | Y7: 1 | Z7: 1 | AA7: 1 | AB7: 1
B8: Lê Đình Phúc | C8: 1 | D8: 1 | E8: 1 | F8: 1 | G8: 1 | H8: 1 | J8: 1 | K8: 1 | L8: 1 | M8: 1 | N8: 1 | O8: 1 | P8: 1 | Q8: 1 | R8: 1 | S8: 1 | T8: 1 | U8: 1 | V8: 1 | W8: 1 | X8: 1 | Y8: 1 | Z8: 1 | AA8: 1 | AB8: 1
B9: Lê Minh Long | C9: 1 | D9: 1 | E9: 1 | F9: 1 | G9: 0.5 | H9: 0.5 | J9: 1 | K9: 1 | L9: 1 | M9: 1 | N9: 1 | O9: 1 | P9: 1 | Q9: 1 | R9: 1 | S9: 1 | T9: 1 | U9: 1 | V9: 1 | W9: 1 | X9: 1 | Y9: 1 | Z9: 1 | AA9: 1 | AB9: 1
B10: Ngô Thị Nhung | C10: 1 | D10: 1 | E10: 1 | F10: 1 | G10: 1 | H10: 1 | J10: 1 | K10: 1 | L10: 1 | M10: 1 | N10: 1 | O10: 1 | P10: 1 | Q10: 1 | R10: 1 | S10: 1 | T10: 1 | U10: 1 | V10: 1 | W10: 1 | X10: 1 | Y10: 1 | Z10: 1 | AA10: 1 | AB10: 1
B11: Nguyễn Thị Trà Giang | C11: 1 | D11: 1 | E11: 1 | F11: 1 | G11: 1 | H11: 1 | J11: 1 | K11: 1 | L11: 1 | M11: 1 | N11: 1 | O11: 1 | P11: 1 | Q11: 1 | R11: 1 | S11: 1 | T11: 1 | U11: 1 | V11: 1 | W11: 1 | X11: 1 | Y11: 1 | Z11: 1 | AA11: 1 | AB11: 1
B12: Nguyễn Việt Lâm | C12: 0.5 | D12: 1 | E12: 1 | F12: 1 | G12: 1 | H12: 1 | J12: 1 | K12: 0.8 | L12: 0.8 | M12: 0.7 | N12: 0.7 | O12: 0.7 | P12: 0.5 | Q12: 0.5 | R12: 0.5 | S12: 0.5 | T12: 0.5 | U12: 0.5 | V12: 0.5 | W12: 0.5 | X12: 0.5 | Y12: 0.5 | Z12: 0.5 | AA12: 0.5 | AB12: 0.5
B13: Trịnh Ngọc Tâm | C13: 0.8 | D13: 0.8 | E13: 0.8 | F13: 1 | G13: 0.75 | H13: 0.75 | J13: 0.75 | K13: 1 | L13: 1 | M13: 1 | N13: 1 | O13: 1 | P13: 1 | Q13: 1 | R13: 1 | S13: 1 | T13: 1 | U13: 1 | V13: 1 | W13: 1 | X13: 1 | Y13: 1 | Z13: 1 | AA13: 1 | AB13: 1
B14: Nguyễn Minh Hiếu | J14: 0.5 | K14: 1 | L14: 1 | M14: 1 | N14: 1 | O14: 1 | P14: 1 | Q14: 1 | R14: 1 | S14: 1 | T14: 1 | U14: 1 | V14: 1 | W14: 1 | X14: 1 | Y14: 1 | Z14: 1 | AA14: 1 | AB14: 1
A15: P.Nghiệp vụ IBS | B15: Đinh Đức Minh | C15: 1 | D15: 1 | E15: 1 | F15: 1 | G15: 1 | H15: 1 | J15: 1 | K15: 1 | L15: 1 | M15: 1 | N15: 1 | O15: 1 | P15: 1 | Q15: 1 | R15: 1 | S15: 1 | T15: 1 | U15: 1 | V15: 1 | W15: 1 | X15: 1 | Y15: 1 | Z15: 1 | AA15: 1 | AB15: 1
B16: Dương Hồng Ngọc | C16: 0.8 | D16: 0.2 | E16: 0.9 | F16: 0.9 | G16: 1 | H16: 1 | J16: 1 | K16: 1 | L16: 1 | M16: 1 | N16: 1 | O16: 1 | P16: 1 | Q16: 1 | R16: 1 | S16: 1 | T16: 1 | U16: 1 | V16: 1 | W16: 1 | X16: 1 | Y16: 1 | Z16: 1 | AA16: 1 | AB16: 1
B17: Hà Mạnh Tân | G17: 0.5 | H17: 0.5 | J17: 0.5 | K17: 0.5 | L17: 0.8 | M17: 0.8 | N17: 0.8 | O17: 0.8 | P17: 0.8 | Q17: 0.8 | R17: 0.8 | S17: 0.8 | T17: 0.8 | U17: 0.8 | V17: 0.8 | W17: 0.8 | X17: 0.8 | Y17: 0.8 | Z17: 0.8 | AA17: 0.8 | AB17: 0.8
B18: Hoàng Tuấn Anh | C18: 1 | D18: 1 | E18: 0.7 | F18: 0.9 | G18: 0.8 | H18: 1 | J18: 0.95 | K18: 1 | L18: 1 | M18: 1 | N18: 1 | O18: 1 | P18: 1 | Q18: 1 | R18: 1 | S18: 1 | T18: 1 | U18: 1 | V18: 1 | W18: 1 | X18: 1 | Y18: 1 | Z18: 1 | AA18: 1 | AB18: 1
B19: Nguyễn Hoàng Tuấn Anh | C19: 0.6 | D19: 0.6 | E19: 0.6 | F19: 0.6 | G19: 0.6 | H19: 0.6 | J19: 0.6 | K19: 1 | L19: 1 | M19: 1 | N19: 1 | O19: 1 | P19: 0.8 | Q19: 0.8 | R19: 0.8 | S19: 0.8 | T19: 0.8 | U19: 0.8 | V19: 0.8 | W19: 0.8 | X19: 0.8 | Y19: 0.8 | Z19: 0.8 | AA19: 0.8 | AB19: 0.8
B20: Nguyễn Lưu Phất | C20: 1 | D20: 1 | E20: 1 | F20: 0.9 | G20: 1 | H20: 0.8 | J20: 0.7 | K20: 0.75 | L20: 0.75 | M20: 0.7 | N20: 0.75 | O20: 0.6 | P20: 0.4 | Q20: 0.4 | R20: 0.4 | S20: 0.4 | T20: 0.4 | U20: 0.4 | V20: 0.4 | W20: 0.4 | X20: 0.4 | Y20: 0.4 | Z20: 0.4 | AA20: 0.4 | AB20: 0.4
B21: Nguyễn Mạnh Thắng | C21: 1 | D21: 1 | E21: 1 | F21: 1 | G21: 1 | H21: 1 | J21: 1 | K21: 1 | L21: 1 | M21: 1 | N21: 1 | O21: 1 | P21: 1 | Q21: 1 | R21: 1 | S21: 1 | T21: 1 | U21: 1 | V21: 1 | W21: 1 | X21: 1 | Y21: 1 | Z21: 1 | AA21: 1 | AB21: 1
B22: Nguyễn Thanh Mai | C22: 1 | D22: 1 | E22: 1 | F22: 1 | G22: 1 | H22: 1 | J22: 0.5 | K22: 1 | L22: 1 | M22: 1 | N22: 1 | O22: 1 | P22: 1 | Q22: 1 | R22: 1 | S22: 1 | T22: 1 | U22: 1 | V22: 1 | W22: 1 | X22: 1 | Y22: 1 | Z22: 1 | AA22: 1 | AB22: 1
B23: Trần Huyền Trang | C23: 1 | D23: 1 | E23: 0.6 | F23: 0.6 | G23: 1 | H23: 1 | J23: 1 | K23: 1 | L23: 1 | M23: 1 | N23: 1 | O23: 1 | P23: 1 | Q23: 1 | R23: 1 | S23: 1 | T23: 1 | U23: 1 | V23: 1 | W23: 1 | X23: 1 | Y23: 1 | Z23: 1 | AA23: 1 | AB23: 1
B24: Trần Thị Thanh Huyền | C24: 0.55 | D24: 1 | E24: 1 | F24: 0.8 | G24: 1 | H24: 1 | J24: 1 | K24: 1 | L24: 1 | M24: 1 | N24: 1 | O24: 1 | P24: 0.5 | Q24: 0.5 | R24: 0.5 | S24: 0.5 | T24: 0.5 | U24: 0.5 | V24: 0.5 | W24: 0.5 | X24: 0.5 | Y24: 0.5 | Z24: 0.5 | AA24: 0.5 | AB24: 0.5
A25: P.Phát triển phần mềm | B25: Bùi Hữu Lâm | E25: 0.8 | F25: 0.8 | G25: 0.6 | H25: 0.3 | J25: 0.8 | K25: 0.85 | L25: 1 | M25: 1 | N25: 1 | O25: 1 | P25: 0.8 | Q25: 0.8 | R25: 0.8 | S25: 1 | T25: 1 | U25: 0.85 | V25: 0.85 | W25: 0.85 | X25: 1 | Y25: 1 | Z25: 1 | AA25: 1 | AB25: 1
B26: Nghiêm Thanh Tùng | E26: 0.7 | F26: 0.7 | G26: 0.7 | H26: 0.2 | J26: 0.7 | K26: 0.81 | L26: 1 | M26: 1 | N26: 1 | O26: 1 | P26: 1 | Q26: 1 | R26: 1 | S26: 0.9 | T26: 0.9 | U26: 0.9 | V26: 0.9 | W26: 0.9 | X26: 0.8 | Y26: 0.8 | Z26: 0.8 | AA26: 0.8 | AB26: 0.8
B27: Nguyễn Anh Đức | E27: 1 | F27: 1 | G27: 1 | H27: 1 | J27: 1 | K27: 1 | L27: 1 | M27: 1 | N27: 1 | O27: 1 | P27: 0.9 | Q27: 0.9 | R27: 0.9 | S27: 0.9 | T27: 0.9 | U27: 0.9 | V27: 0.9 | W27: 0.9 | X27: 0.9 | Y27: 0.9 | Z27: 0.9 | AA27: 0.9 | AB27: 0.9
B28: Nguyễn Khắc Mạnh | E28: 0.5 | F28: 0.7 | G28: 0.7 | H28: 0.7 | J28: 0.7 | K28: 0.92 | L28: 0.92 | M28: 0.92 | N28: 0.92 | O28: 0.92 | P28: 0.82 | Q28: 0.82 | R28: 0.82 | S28: 0.82 | T28: 0.82 | U28: 0.82 | V28: 0.82 | W28: 0.82 | X28: 0.82 | Y28: 0.82 | Z28: 0.82 | AA28: 0.82 | AB28: 0.82
B29: Nguyễn Văn Diên | E29: 0.8 | F29: 1 | G29: 1 | H29: 0.7 | J29: 0.5 | K29: 0.92 | L29: 0.82 | M29: 0.82 | N29: 0.82 | O29: 0.82 | P29: 0.92 | Q29: 1 | R29: 1 | S29: 1 | T29: 1 | U29: 0.92 | V29: 0.92 | W29: 0.92 | X29: 0.92 | Y29: 0.92 | Z29: 0.92 | AA29: 0.92 | AB29: 0.92
B30: Phí Quang Vinh | E30: 0.7 | F30: 0.9 | G30: 0.9 | H30: 0.6 | J30: 1 | K30: 1 | L30: 0.94 | M30: 0.94 | N30: 0.94 | O30: 0.94 | P30: 0.94 | Q30: 0.94 | R30: 0.94 | S30: 0.94 | T30: 0.94 | U30: 0.94 | V30: 0.94 | W30: 0.94 | X30: 0.94 | Y30: 0.94 | Z30: 0.94 | AA30: 0.94 | AB30: 0.94
B31: Vương Duy Long | E31: 0.9 | F31: 0.9 | G31: 0.8 | H31: 0.7 | J31: 0.7 | K31: 0.91 | L31: 0.91 | M31: 0.91 | N31: 0.91 | O31: 0.91 | P31: 0.91 | Q31: 0.91 | R31: 0.91 | S31: 0.91 | T31: 0.91 | U31: 0.91 | V31: 0.91 | W31: 0.91 | X31: 0.91 | Y31: 0.91 | Z31: 0.91 | AA31: 0.91 | AB31: 0.91
A32: (blank) | B32: (blank)

Sheet Resource Plan
A1: ID nhân viên | B1: Họ và Tên | C1: Phòng | D1: Trạng thái nhân viên | E1: Mã dự án | F1: Tên dự án | G1: PM | H1: Trạng thái dự án | I1: Lọc trùng | J1: 46027 | K1: =J1+7 -> 46034 | L1: =K1+7 -> 46041 | M1: =L1+7 -> 46048 | N1: =M1+7 -> 46055 | O1: =N1+7 -> 46062 | P1: =O1+7 -> 46069 | Q1: =P1+7 -> 46076 | R1: =Q1+7 -> 46083 | ... BI1: =BH1+7 -> 46384
A2: tamtn | B2: =IF(A2="","",VLOOKUP(A2,'DS Nhân viên'!B:C,2,FALSE)) -> Trịnh Ngọc Tâm | C2: =IF(A2="","",VLOOKUP(A2,'DS Nhân viên'!B:D,3,FALSE)) -> P.Kỹ thuật IBS | D2: =IF(A2="","",VLOOKUP(A2,'DS Nhân viên'!$B:$F,5,FALSE)) -> Chính thức | E2: B_MB_ARCHIVE | F2: =IF($E2="","",VLOOKUP($E2,'DS Dự án'!$B:$F,2,FALSE)) -> B_MB_ARCHIVE | G2: =IF($E2="","",VLOOKUP($E2,'DS Dự án'!$B:$F,4,FALSE)) -> NgocDH | H2: =IF($E2="","",VLOOKUP(E2,'DS Dự án'!$B:$F,5,0)) -> Đang thực hiện (Đã có hợp đồng) | I2: =A2&E2 -> tamtnB_MB_ARCHIVE | J2: 0.8 | K2: 0.8 | L2: 0.8 | M2: 0.8 | N2: 0.35 | O2: 0.35 | Q2: 0.35
A3: ngocdh | B3: =IF(A3="","",VLOOKUP(A3,'DS Nhân viên'!B:C,2,FALSE)) -> Dương Hồng Ngọc | C3: =IF(A3="","",VLOOKUP(A3,'DS Nhân viên'!B:D,3,FALSE)) -> P.Nghiệp vụ IBS | D3: =IF(A3="","",VLOOKUP(A3,'DS Nhân viên'!$B:$F,5,FALSE)) -> Chính thức | E3: B_MB_ARCHIVE | F3: =IF($E3="","",VLOOKUP($E3,'DS Dự án'!$B:$F,2,FALSE)) -> B_MB_ARCHIVE | G3: =IF($E3="","",VLOOKUP($E3,'DS Dự án'!$B:$F,4,FALSE)) -> NgocDH | H3: =IF($E3="","",VLOOKUP(E3,'DS Dự án'!$B:$F,5,0)) -> Đang thực hiện (Đã có hợp đồng) | I3: =A3&E3 -> ngocdhB_MB_ARCHIVE | J3: 0.3 | K3: 0.1 | L3: 0.1 | M3: 0.1 | N3: 0.1 | O3: 0.1 | Q3: 0.1
A4: longlm | B4: =IF(A4="","",VLOOKUP(A4,'DS Nhân viên'!B:C,2,FALSE)) -> Lê Minh Long | C4: =IF(A4="","",VLOOKUP(A4,'DS Nhân viên'!B:D,3,FALSE)) -> P.Kỹ thuật IBS | D4: =IF(A4="","",VLOOKUP(A4,'DS Nhân viên'!$B:$F,5,FALSE)) -> Học việc | E4: B_MB_ARCHIVE | F4: =IF($E4="","",VLOOKUP($E4,'DS Dự án'!$B:$F,2,FALSE)) -> B_MB_ARCHIVE | G4: =IF($E4="","",VLOOKUP($E4,'DS Dự án'!$B:$F,4,FALSE)) -> NgocDH | H4: =IF($E4="","",VLOOKUP(E4,'DS Dự án'!$B:$F,5,0)) -> Đang thực hiện (Đã có hợp đồng) | I4: =A4&E4 -> longlmB_MB_ARCHIVE | J4: 1 | K4: 1 | L4: 1 | M4: 1 | N4: 0.5 | O4: 0.5 | Q4: 1 | R4: 1
A5: conglc | B5: =IF(A5="","",VLOOKUP(A5,'DS Nhân viên'!B:C,2,FALSE)) -> Lê Chí Công | C5: =IF(A5="","",VLOOKUP(A5,'DS Nhân viên'!B:D,3,FALSE)) -> P.Kỹ thuật IBS | D5: =IF(A5="","",VLOOKUP(A5,'DS Nhân viên'!$B:$F,5,FALSE)) -> Chính thức | E5: B_MB_ARCHIVE | F5: =IF($E5="","",VLOOKUP($E5,'DS Dự án'!$B:$F,2,FALSE)) -> B_MB_ARCHIVE | G5: =IF($E5="","",VLOOKUP($E5,'DS Dự án'!$B:$F,4,FALSE)) -> NgocDH | H5: =IF($E5="","",VLOOKUP(E5,'DS Dự án'!$B:$F,5,0)) -> Đang thực hiện (Đã có hợp đồng) | I5: =A5&E5 -> conglcB_MB_ARCHIVE | J5: 0.25 | K5: 0.5 | L5: 0.3 | M5: 0.25 | N5: 0.3 | O5: 0.3
A6: thangnm | B6: =IF(A6="","",VLOOKUP(A6,'DS Nhân viên'!B:C,2,FALSE)) -> Nguyễn Mạnh Thắng | C6: =IF(A6="","",VLOOKUP(A6,'DS Nhân viên'!B:D,3,FALSE)) -> P.Nghiệp vụ IBS | D6: =IF(A6="","",VLOOKUP(A6,'DS Nhân viên'!$B:$F,5,FALSE)) -> Chính thức | E6: B_VNA_RPS | F6: =IF($E6="","",VLOOKUP($E6,'DS Dự án'!$B:$F,2,FALSE)) -> B_VNA_RPS | G6: =IF($E6="","",VLOOKUP($E6,'DS Dự án'!$B:$F,4,FALSE)) -> AnhNHT | H6: =IF($E6="","",VLOOKUP(E6,'DS Dự án'!$B:$F,5,0)) -> Đang thực hiện (Đã có hợp đồng) | I6: =A6&E6 -> thangnmB_VNA_RPS | J6: 1 | K6: 1 | L6: 1 | M6: 1 | N6: 1 | O6: 1 | Q6: 1 | R6: 1 | S6: 1 | T6: 1 | U6: 1 | V6: 1 | W6: 1 | X6: 1 | Y6: 1 | Z6: 1 | AA6: 1 | AB6: 1 | AC6: 1 | AD6: 1 | AE6: 1 | AF6: 1 | AG6: 1 | AH6: 1 | AI6: 1
A7: ngocdh | B7: =IF(A7="","",VLOOKUP(A7,'DS Nhân viên'!B:C,2,FALSE)) -> Dương Hồng Ngọc | C7: =IF(A7="","",VLOOKUP(A7,'DS Nhân viên'!B:D,3,FALSE)) -> P.Nghiệp vụ IBS | D7: =IF(A7="","",VLOOKUP(A7,'DS Nhân viên'!$B:$F,5,FALSE)) -> Chính thức | E7: B_VNA_RPS | F7: =IF($E7="","",VLOOKUP($E7,'DS Dự án'!$B:$F,2,FALSE)) -> B_VNA_RPS | G7: =IF($E7="","",VLOOKUP($E7,'DS Dự án'!$B:$F,4,FALSE)) -> AnhNHT | H7: =IF($E7="","",VLOOKUP(E7,'DS Dự án'!$B:$F,5,0)) -> Đang thực hiện (Đã có hợp đồng) | I7: =A7&E7 -> ngocdhB_VNA_RPS | J7: 0.5 | K7: 0.1 | L7: 0.1 | M7: 0.1 | N7: 0.1 | O7: 0.1 | Q7: 0.1 | R7: 0.1 | S7: 0.1 | T7: 0.1 | U7: 0.1 | V7: 0.1 | W7: 0.1 | X7: 0.1 | Y7: 0.1 | Z7: 0.1 | AA7: 0.1 | AB7: 0.1 | AC7: 0.1 | AD7: 0.1 | AE7: 0.1 | AF7: 0.1 | AG7: 0.1 | AH7: 0.1 | AI7: 0.1
A8: lamnv | B8: =IF(A8="","",VLOOKUP(A8,'DS Nhân viên'!B:C,2,FALSE)) -> Nguyễn Việt Lâm | C8: =IF(A8="","",VLOOKUP(A8,'DS Nhân viên'!B:D,3,FALSE)) -> P.Kỹ thuật IBS | D8: =IF(A8="","",VLOOKUP(A8,'DS Nhân viên'!$B:$F,5,FALSE)) -> Học việc | E8: B_VNA_RPS | F8: =IF($E8="","",VLOOKUP($E8,'DS Dự án'!$B:$F,2,FALSE)) -> B_VNA_RPS | G8: =IF($E8="","",VLOOKUP($E8,'DS Dự án'!$B:$F,4,FALSE)) -> AnhNHT | H8: =IF($E8="","",VLOOKUP(E8,'DS Dự án'!$B:$F,5,0)) -> Đang thực hiện (Đã có hợp đồng) | I8: =A8&E8 -> lamnvB_VNA_RPS | J8: 0.5 | K8: 1 | L8: 1 | M8: 1 | N8: 1 | O8: 1 | Q8: 0.85 | R8: 0.5 | S8: 0.5 | T8: 0.5 | U8: 0.5 | V8: 0.5 | W8: 0.5 | X8: 0.5 | Y8: 0.5 | Z8: 0.5 | AA8: 0.5 | AB8: 0.5 | AC8: 0.5 | AD8: 0.5 | AE8: 0.5 | AF8: 0.5 | AG8: 0.5 | AH8: 0.5 | AI8: 0.5
A9: anhnht | B9: =IF(A9="","",VLOOKUP(A9,'DS Nhân viên'!B:C,2,FALSE)) -> Nguyễn Hoàng Tuấn Anh | C9: =IF(A9="","",VLOOKUP(A9,'DS Nhân viên'!B:D,3,FALSE)) -> P.Nghiệp vụ IBS | D9: =IF(A9="","",VLOOKUP(A9,'DS Nhân viên'!$B:$F,5,FALSE)) -> Chính thức | E9: B_VNA_RPS | F9: =IF($E9="","",VLOOKUP($E9,'DS Dự án'!$B:$F,2,FALSE)) -> B_VNA_RPS | G9: =IF($E9="","",VLOOKUP($E9,'DS Dự án'!$B:$F,4,FALSE)) -> AnhNHT | H9: =IF($E9="","",VLOOKUP(E9,'DS Dự án'!$B:$F,5,0)) -> Đang thực hiện (Đã có hợp đồng) | I9: =A9&E9 -> anhnhtB_VNA_RPS
A10: tamtn | B10: =IF(A10="","",VLOOKUP(A10,'DS Nhân viên'!B:C,2,FALSE)) -> Trịnh Ngọc Tâm | C10: =IF(A10="","",VLOOKUP(A10,'DS Nhân viên'!B:D,3,FALSE)) -> P.Kỹ thuật IBS | D10: =IF(A10="","",VLOOKUP(A10,'DS Nhân viên'!$B:$F,5,FALSE)) -> Chính thức | E10: BD_ID0_01_00 | F10: =IF($E10="","",VLOOKUP($E10,'DS Dự án'!$B:$F,2,FALSE)) -> BI DATA INDEVCO | G10: =IF($E10="","",VLOOKUP($E10,'DS Dự án'!$B:$F,4,FALSE)) -> AnhHT | H10: =IF($E10="","",VLOOKUP(E10,'DS Dự án'!$B:$F,5,0)) -> Đang thực hiện (Đã có hợp đồng) | I10: =A10&E10 -> tamtnBD_ID0_01_00 | M10: 0.2 | N10: 0.4 | O10: 0.4 | Q10: 0.4 | R10: 0.3 | S10: 0.3 | T10: 0.3 | U10: 0.3 | V10: 0.3 | W10: 0.3 | X10: 0.3 | Y10: 0.3 | Z10: 0.3 | AA10: 0.3 | AB10: 0.3 | AC10: 0.3 | AD10: 0.3 | AE10: 0.3 | AF10: 0.3 | AG10: 0.3 | AH10: 0.3 | AI10: 0.3
A11: anhht | B11: =IF(A11="","",VLOOKUP(A11,'DS Nhân viên'!B:C,2,FALSE)) -> Hoàng Tuấn Anh | C11: =IF(A11="","",VLOOKUP(A11,'DS Nhân viên'!B:D,3,FALSE)) -> P.Nghiệp vụ IBS | D11: =IF(A11="","",VLOOKUP(A11,'DS Nhân viên'!$B:$F,5,FALSE)) -> Chính thức | E11: BD_ID0_01_00 | F11: =IF($E11="","",VLOOKUP($E11,'DS Dự án'!$B:$F,2,FALSE)) -> BI DATA INDEVCO | G11: =IF($E11="","",VLOOKUP($E11,'DS Dự án'!$B:$F,4,FALSE)) -> AnhHT | H11: =IF($E11="","",VLOOKUP(E11,'DS Dự án'!$B:$F,5,0)) -> Đang thực hiện (Đã có hợp đồng) | I11: =A11&E11 -> anhhtBD_ID0_01_00 | M11: 0.2 | N11: 0.2 | O11: 0.1 | R11: 0.15 | S11: 0.15 | T11: 0.15 | V11: 0.15 | W11: 0.15 | X11: 0.15 | Z11: 0.15 | AA11: 0.15 | AB11: 0.15 | AD11: 0.15 | AE11: 0.15 | AF11: 0.15 | AH11: 0.15 | AI11: 0.15
A12: nhungnt2 | B12: =IF(A12="","",VLOOKUP(A12,'DS Nhân viên'!B:C,2,FALSE)) -> Ngô Thị Nhung | C12: P.Kỹ thuật IBS | D12: =IF(A12="","",VLOOKUP(A12,'DS Nhân viên'!$B:$F,5,FALSE)) -> Chính thức | E12: BD_GE0_01_00 | F12: =IF($E12="","",VLOOKUP($E12,'DS Dự án'!$B:$F,2,FALSE)) -> BI DWH GELEXIMCO | G12: =IF($E12="","",VLOOKUP($E12,'DS Dự án'!$B:$F,4,FALSE)) -> AnhNHT | H12: =IF($E12="","",VLOOKUP(E12,'DS Dự án'!$B:$F,5,0)) -> Đang thực hiện (Đã có hợp đồng) | I12: =A12&E12 -> nhungnt2BD_GE0_01_00 | J12: 1 | K12: 1 | L12: 1 | M12: 1 | N12: 0.6
A13: minhdd | B13: =IF(A13="","",VLOOKUP(A13,'DS Nhân viên'!B:C,2,FALSE)) -> Đinh Đức Minh | C13: =IF(A13="","",VLOOKUP(A13,'DS Nhân viên'!B:D,3,FALSE)) -> P.Nghiệp vụ IBS | D13: =IF(A13="","",VLOOKUP(A13,'DS Nhân viên'!$B:$F,5,FALSE)) -> Chính thức | E13: BD_GE0_01_00 | F13: =IF($E13="","",VLOOKUP($E13,'DS Dự án'!$B:$F,2,FALSE)) -> BI DWH GELEXIMCO | G13: =IF($E13="","",VLOOKUP($E13,'DS Dự án'!$B:$F,4,FALSE)) -> AnhNHT | H13: =IF($E13="","",VLOOKUP(E13,'DS Dự án'!$B:$F,5,0)) -> Đang thực hiện (Đã có hợp đồng) | I13: =A13&E13 -> minhddBD_GE0_01_00 | J13: 1 | K13: 1 | L13: 1 | M13: 1 | N13: 1 | O13: 1 | Q13: 1 | R13: 1 | S13: 0.5 | W13: 0.5 | X13: 0.5 | Y13: 0.5 | Z13: 0.5 | AA13: 1 | AB13: 1 | AC13: 1 | AD13: 1 | AE13: 1 | AF13: 1 | AG13: 1 | AH13: 1 | AI13: 1
A14: maint | B14: =IF(A14="","",VLOOKUP(A14,'DS Nhân viên'!B:C,2,FALSE)) -> Nguyễn Thanh Mai | C14: =IF(A14="","",VLOOKUP(A14,'DS Nhân viên'!B:D,3,FALSE)) -> P.Nghiệp vụ IBS | D14: =IF(A14="","",VLOOKUP(A14,'DS Nhân viên'!$B:$F,5,FALSE)) -> Chính thức | E14: BD_GE0_01_00 | F14: =IF($E14="","",VLOOKUP($E14,'DS Dự án'!$B:$F,2,FALSE)) -> BI DWH GELEXIMCO | G14: =IF($E14="","",VLOOKUP($E14,'DS Dự án'!$B:$F,4,FALSE)) -> AnhNHT | H14: =IF($E14="","",VLOOKUP(E14,'DS Dự án'!$B:$F,5,0)) -> Đang thực hiện (Đã có hợp đồng) | I14: =A14&E14 -> maintBD_GE0_01_00 | J14: 1 | K14: 1 | L14: 1 | M14: 1 | N14: 1 | O14: 1 | Q14: 0.5 | R14: 0.5 | S14: 0.5 | T14: 0.5 | U14: 0.5 | V14: 0.5 | W14: 0.5 | X14: 0.5 | Y14: 0.5 | Z14: 0.5 | AA14: 0.5 | AB14: 0.5 | AC14: 0.5 | AD14: 0.5 | AE14: 0.5 | AF14: 0.5 | AG14: 0.5 | AH14: 0.5 | AI14: 0.5
A15: lamnv | B15: =IF(A15="","",VLOOKUP(A15,'DS Nhân viên'!B:C,2,FALSE)) -> Nguyễn Việt Lâm | C15: =IF(A15="","",VLOOKUP(A15,'DS Nhân viên'!B:D,3,FALSE)) -> P.Kỹ thuật IBS | D15: =IF(A15="","",VLOOKUP(A15,'DS Nhân viên'!$B:$F,5,FALSE)) -> Học việc | E15: BD_GE0_01_00 | F15: =IF($E15="","",VLOOKUP($E15,'DS Dự án'!$B:$F,2,FALSE)) -> BI DWH GELEXIMCO | G15: =IF($E15="","",VLOOKUP($E15,'DS Dự án'!$B:$F,4,FALSE)) -> AnhNHT | H15: =IF($E15="","",VLOOKUP(E15,'DS Dự án'!$B:$F,5,0)) -> Đang thực hiện (Đã có hợp đồng) | I15: =A15&E15 -> lamnvBD_GE0_01_00
A16: hieudt | B16: =IF(A16="","",VLOOKUP(A16,'DS Nhân viên'!B:C,2,FALSE)) -> Đỗ Trung Hiếu | C16: =IF(A16="","",VLOOKUP(A16,'DS Nhân viên'!B:D,3,FALSE)) -> P.Kỹ thuật IBS | D16: =IF(A16="","",VLOOKUP(A16,'DS Nhân viên'!$B:$F,5,FALSE)) -> Học việc | E16: BD_GE0_01_00 | F16: =IF($E16="","",VLOOKUP($E16,'DS Dự án'!$B:$F,2,FALSE)) -> BI DWH GELEXIMCO | G16: =IF($E16="","",VLOOKUP($E16,'DS Dự án'!$B:$F,4,FALSE)) -> AnhNHT | H16: =IF($E16="","",VLOOKUP(E16,'DS Dự án'!$B:$F,5,0)) -> Đang thực hiện (Đã có hợp đồng) | I16: =A16&E16 -> hieudtBD_GE0_01_00 | J16: 1 | K16: 1 | L16: 1 | M16: 1 | N16: 1 | O16: 1 | Q16: 0.5 | R16: 1 | S16: 1 | T16: 0.7 | U16: 0.7 | V16: 0.7 | W16: 1 | X16: 1 | Y16: 1 | Z16: 1 | AA16: 1 | AB16: 1 | AC16: 1 | AD16: 1 | AE16: 1 | AF16: 1 | AG16: 1 | AH16: 1 | AI16: 1
A17: anhnht | B17: =IF(A17="","",VLOOKUP(A17,'DS Nhân viên'!B:C,2,FALSE)) -> Nguyễn Hoàng Tuấn Anh | C17: =IF(A17="","",VLOOKUP(A17,'DS Nhân viên'!B:D,3,FALSE)) -> P.Nghiệp vụ IBS | D17: =IF(A17="","",VLOOKUP(A17,'DS Nhân viên'!$B:$F,5,FALSE)) -> Chính thức | E17: BD_GE0_01_00 | F17: =IF($E17="","",VLOOKUP($E17,'DS Dự án'!$B:$F,2,FALSE)) -> BI DWH GELEXIMCO | G17: =IF($E17="","",VLOOKUP($E17,'DS Dự án'!$B:$F,4,FALSE)) -> AnhNHT | H17: =IF($E17="","",VLOOKUP(E17,'DS Dự án'!$B:$F,5,0)) -> Đang thực hiện (Đã có hợp đồng) | I17: =A17&E17 -> anhnhtBD_GE0_01_00 | J17: 0.6 | K17: 0.6 | L17: 0.6 | M17: 0.6 | N17: 0.6 | O17: 0.6 | Q17: 0.6 | R17: 0.6 | S17: 0.6 | T17: 0.6 | U17: 0.6 | V17: 0.6 | W17: 0.6 | X17: 0.6 | Y17: 0.6 | Z17: 0.6 | AA17: 0.6 | AB17: 0.6 | AC17: 0.6 | AD17: 0.6 | AE17: 0.6 | AF17: 0.6 | AG17: 0.6 | AH17: 0.6 | AI17: 0.6
A18: hieunm | B18: =IF(A18="","",VLOOKUP(A18,'DS Nhân viên'!B:C,2,FALSE)) -> Nguyễn Minh Hiếu | C18: =IF(A18="","",VLOOKUP(A18,'DS Nhân viên'!B:D,3,FALSE)) -> P.Kỹ thuật IBS | D18: =IF(A18="","",VLOOKUP(A18,'DS Nhân viên'!$B:$F,5,FALSE)) -> Thử việc | E18: BD_GE0_01_00 | F18: =IF($E18="","",VLOOKUP($E18,'DS Dự án'!$B:$F,2,FALSE)) -> BI DWH GELEXIMCO | G18: =IF($E18="","",VLOOKUP($E18,'DS Dự án'!$B:$F,4,FALSE)) -> AnhNHT | H18: =IF($E18="","",VLOOKUP(E18,'DS Dự án'!$B:$F,5,0)) -> Đang thực hiện (Đã có hợp đồng) | I18: =A18&E18 -> hieunmBD_GE0_01_00 | Q18: 0.5 | R18: 1 | S18: 1 | T18: 1 | U18: 1 | V18: 1 | W18: 1 | X18: 1 | Y18: 1 | Z18: 1 | AA18: 1 | AB18: 1 | AC18: 1 | AD18: 1 | AE18: 1 | AF18: 1 | AG18: 1 | AH18: 1 | AI18: 1
A19: tanhm | B19: =IF(A19="","",VLOOKUP(A19,'DS Nhân viên'!B:C,2,FALSE)) -> Hà Mạnh Tân | C19: =IF(A19="","",VLOOKUP(A19,'DS Nhân viên'!B:D,3,FALSE)) -> P.Nghiệp vụ IBS | D19: =IF(A19="","",VLOOKUP(A19,'DS Nhân viên'!$B:$F,5,FALSE)) -> Chính thức | E19: BD_EN4_01_00 | F19: =IF($E19="","",VLOOKUP($E19,'DS Dự án'!$B:$F,2,FALSE)) -> BI EVN HCM GD2 | G19: =IF($E19="","",VLOOKUP($E19,'DS Dự án'!$B:$F,4,FALSE)) -> AnhNHT | H19: =IF($E19="","",VLOOKUP(E19,'DS Dự án'!$B:$F,5,0)) -> Cơ hội | I19: =A19&E19 -> tanhmBD_EN4_01_00
A20: phatnl | B20: =IF(A20="","",VLOOKUP(A20,'DS Nhân viên'!B:C,2,FALSE)) -> Nguyễn Lưu Phất | C20: =IF(A20="","",VLOOKUP(A20,'DS Nhân viên'!B:D,3,FALSE)) -> P.Nghiệp vụ IBS | D20: =IF(A20="","",VLOOKUP(A20,'DS Nhân viên'!$B:$F,5,FALSE)) -> Chính thức | E20: BD_EN4_01_00 | F20: =IF($E20="","",VLOOKUP($E20,'DS Dự án'!$B:$F,2,FALSE)) -> BI EVN HCM GD2 | G20: =IF($E20="","",VLOOKUP($E20,'DS Dự án'!$B:$F,4,FALSE)) -> AnhNHT | H20: =IF($E20="","",VLOOKUP(E20,'DS Dự án'!$B:$F,5,0)) -> Cơ hội | I20: =A20&E20 -> phatnlBD_EN4_01_00 | J20: 0.2 | K20: 0.2 | L20: 0.2 | M20: 0.2 | N20: 0.2 | O20: 0.2 | Q20: 0.3 | R20: 0.05 | S20: 0.1 | T20: 0 | U20: 0.2 | V20: 0.2
A21: anhnht | B21: =IF(A21="","",VLOOKUP(A21,'DS Nhân viên'!B:C,2,FALSE)) -> Nguyễn Hoàng Tuấn Anh | C21: =IF(A21="","",VLOOKUP(A21,'DS Nhân viên'!B:D,3,FALSE)) -> P.Nghiệp vụ IBS | D21: =IF(A21="","",VLOOKUP(A21,'DS Nhân viên'!$B:$F,5,FALSE)) -> Chính thức | E21: BD_EN4_01_00 | F21: =IF($E21="","",VLOOKUP($E21,'DS Dự án'!$B:$F,2,FALSE)) -> BI EVN HCM GD2 | G21: =IF($E21="","",VLOOKUP($E21,'DS Dự án'!$B:$F,4,FALSE)) -> AnhNHT | H21: =IF($E21="","",VLOOKUP(E21,'DS Dự án'!$B:$F,5,0)) -> Cơ hội | I21: =A21&E21 -> anhnhtBD_EN4_01_00
A22: huyenttt | B22: =IF(A22="","",VLOOKUP(A22,'DS Nhân viên'!B:C,2,FALSE)) -> Trần Thị Thanh Huyền | C22: =IF(A22="","",VLOOKUP(A22,'DS Nhân viên'!B:D,3,FALSE)) -> P.Nghiệp vụ IBS | D22: =IF(A22="","",VLOOKUP(A22,'DS Nhân viên'!$B:$F,5,FALSE)) -> Chính thức | E22: BD_EN4_01_00 | F22: =IF($E22="","",VLOOKUP($E22,'DS Dự án'!$B:$F,2,FALSE)) -> BI EVN HCM GD2 | G22: =IF($E22="","",VLOOKUP($E22,'DS Dự án'!$B:$F,4,FALSE)) -> AnhNHT | H22: =IF($E22="","",VLOOKUP(E22,'DS Dự án'!$B:$F,5,0)) -> Cơ hội | I22: =A22&E22 -> huyentttBD_EN4_01_00 | J22: 0 | K22: 0 | L22: 0 | M22: 0 | N22: 0 | O22: 0 | Q22: 0 | R22: 0 | S22: 0 | T22: 0 | U22: 0 | V22: 0
A23: ngocdh | B23: =IF(A23="","",VLOOKUP(A23,'DS Nhân viên'!B:C,2,FALSE)) -> Dương Hồng Ngọc | C23: =IF(A23="","",VLOOKUP(A23,'DS Nhân viên'!B:D,3,FALSE)) -> P.Nghiệp vụ IBS | D23: =IF(A23="","",VLOOKUP(A23,'DS Nhân viên'!$B:$F,5,FALSE)) -> Chính thức | E23: BD_EN1_01_00 | F23: =IF($E23="","",VLOOKUP($E23,'DS Dự án'!$B:$F,2,FALSE)) -> BI GENCO1 2025 | G23: =IF($E23="","",VLOOKUP($E23,'DS Dự án'!$B:$F,4,FALSE)) -> AnhNHT | H23: =IF($E23="","",VLOOKUP(E23,'DS Dự án'!$B:$F,5,0)) -> Đóng | I23: =A23&E23 -> ngocdhBD_EN1_01_00 | J23: 0.1
A24: trangth | B24: =IF(A24="","",VLOOKUP(A24,'DS Nhân viên'!B:C,2,FALSE)) -> Trần Huyền Trang | C24: =IF(A24="","",VLOOKUP(A24,'DS Nhân viên'!B:D,3,FALSE)) -> P.Nghiệp vụ IBS | D24: =IF(A24="","",VLOOKUP(A24,'DS Nhân viên'!$B:$F,5,FALSE)) -> Chính thức | E24: B_MB_AUTOMATION_QA_CNTT | F24: =IF($E24="","",VLOOKUP($E24,'DS Dự án'!$B:$F,2,FALSE)) -> BI MB QA | G24: =IF($E24="","",VLOOKUP($E24,'DS Dự án'!$B:$F,4,FALSE)) -> CongLC | H24: =IF($E24="","",VLOOKUP(E24,'DS Dự án'!$B:$F,5,0)) -> Đóng | I24: =A24&E24 -> trangthB_MB_AUTOMATION_QA_CNTT
A25: phucld | B25: =IF(A25="","",VLOOKUP(A25,'DS Nhân viên'!B:C,2,FALSE)) -> Lê Đình Phúc | C25: =IF(A25="","",VLOOKUP(A25,'DS Nhân viên'!B:D,3,FALSE)) -> P.Kỹ thuật IBS | D25: =IF(A25="","",VLOOKUP(A25,'DS Nhân viên'!$B:$F,5,FALSE)) -> Chính thức | E25: B_MB_AUTOMATION_QA_CNTT | F25: =IF($E25="","",VLOOKUP($E25,'DS Dự án'!$B:$F,2,FALSE)) -> BI MB QA | G25: =IF($E25="","",VLOOKUP($E25,'DS Dự án'!$B:$F,4,FALSE)) -> CongLC | H25: =IF($E25="","",VLOOKUP(E25,'DS Dự án'!$B:$F,5,0)) -> Đóng | I25: =A25&E25 -> phucldB_MB_AUTOMATION_QA_CNTT
A26: nhungnt2 | B26: =IF(A26="","",VLOOKUP(A26,'DS Nhân viên'!B:C,2,FALSE)) -> Ngô Thị Nhung | C26: =IF(A26="","",VLOOKUP(A26,'DS Nhân viên'!B:D,3,FALSE)) -> P.Kỹ thuật IBS | D26: =IF(A26="","",VLOOKUP(A26,'DS Nhân viên'!$B:$F,5,FALSE)) -> Chính thức | E26: B_MB_AUTOMATION_QA_CNTT | F26: =IF($E26="","",VLOOKUP($E26,'DS Dự án'!$B:$F,2,FALSE)) -> BI MB QA | G26: =IF($E26="","",VLOOKUP($E26,'DS Dự án'!$B:$F,4,FALSE)) -> CongLC | H26: =IF($E26="","",VLOOKUP(E26,'DS Dự án'!$B:$F,5,0)) -> Đóng | I26: =A26&E26 -> nhungnt2B_MB_AUTOMATION_QA_CNTT
A27: ngocdh | B27: =IF(A27="","",VLOOKUP(A27,'DS Nhân viên'!B:C,2,FALSE)) -> Dương Hồng Ngọc | C27: =IF(A27="","",VLOOKUP(A27,'DS Nhân viên'!B:D,3,FALSE)) -> P.Nghiệp vụ IBS | D27: =IF(A27="","",VLOOKUP(A27,'DS Nhân viên'!$B:$F,5,FALSE)) -> Chính thức | E27: B_MB_AUTOMATION_QA_CNTT | F27: =IF($E27="","",VLOOKUP($E27,'DS Dự án'!$B:$F,2,FALSE)) -> BI MB QA | G27: =IF($E27="","",VLOOKUP($E27,'DS Dự án'!$B:$F,4,FALSE)) -> CongLC | H27: =IF($E27="","",VLOOKUP(E27,'DS Dự án'!$B:$F,5,0)) -> Đóng | I27: =A27&E27 -> ngocdhB_MB_AUTOMATION_QA_CNTT
A28: conglc | B28: =IF(A28="","",VLOOKUP(A28,'DS Nhân viên'!B:C,2,FALSE)) -> Lê Chí Công | C28: =IF(A28="","",VLOOKUP(A28,'DS Nhân viên'!B:D,3,FALSE)) -> P.Kỹ thuật IBS | D28: =IF(A28="","",VLOOKUP(A28,'DS Nhân viên'!$B:$F,5,FALSE)) -> Chính thức | E28: B_MB_AUTOMATION_QA_CNTT | F28: =IF($E28="","",VLOOKUP($E28,'DS Dự án'!$B:$F,2,FALSE)) -> BI MB QA | G28: =IF($E28="","",VLOOKUP($E28,'DS Dự án'!$B:$F,4,FALSE)) -> CongLC | H28: =IF($E28="","",VLOOKUP(E28,'DS Dự án'!$B:$F,5,0)) -> Đóng | I28: =A42&E42
A29: trangth | B29: =IF(A29="","",VLOOKUP(A29,'DS Nhân viên'!B:C,2,FALSE)) -> Trần Huyền Trang | C29: =IF(A29="","",VLOOKUP(A29,'DS Nhân viên'!B:D,3,FALSE)) -> P.Nghiệp vụ IBS | D29: =IF(A29="","",VLOOKUP(A29,'DS Nhân viên'!$B:$F,5,FALSE)) -> Chính thức | E29: B_MB_QLDT | F29: =IF($E29="","",VLOOKUP($E29,'DS Dự án'!$B:$F,2,FALSE)) -> BI MB QLĐT | G29: =IF($E29="","",VLOOKUP($E29,'DS Dự án'!$B:$F,4,FALSE)) -> CongLC | H29: =IF($E29="","",VLOOKUP(E29,'DS Dự án'!$B:$F,5,0)) -> Đang thực hiện (Đã có hợp đồng) | I29: =A29&E29 -> trangthB_MB_QLDT | J29: 0.3 | K29: 0.3 | L29: 0.3 | M29: 0.3 | N29: 0.5 | O29: 0.5 | Q29: 0.5
A30: tanhm | B30: =IF(A30="","",VLOOKUP(A30,'DS Nhân viên'!B:C,2,FALSE)) -> Hà Mạnh Tân | C30: =IF(A30="","",VLOOKUP(A30,'DS Nhân viên'!B:D,3,FALSE)) -> P.Nghiệp vụ IBS | D30: =IF(A30="","",VLOOKUP(A30,'DS Nhân viên'!$B:$F,5,FALSE)) -> Chính thức | E30: B_MB_QLDT | F30: =IF($E30="","",VLOOKUP($E30,'DS Dự án'!$B:$F,2,FALSE)) -> BI MB QLĐT | G30: =IF($E30="","",VLOOKUP($E30,'DS Dự án'!$B:$F,4,FALSE)) -> CongLC | H30: =IF($E30="","",VLOOKUP(E30,'DS Dự án'!$B:$F,5,0)) -> Đang thực hiện (Đã có hợp đồng) | I30: =A30&E30 -> tanhmB_MB_QLDT
A31: phucld | B31: =IF(A31="","",VLOOKUP(A31,'DS Nhân viên'!B:C,2,FALSE)) -> Lê Đình Phúc | C31: =IF(A31="","",VLOOKUP(A31,'DS Nhân viên'!B:D,3,FALSE)) -> P.Kỹ thuật IBS | D31: =IF(A31="","",VLOOKUP(A31,'DS Nhân viên'!$B:$F,5,FALSE)) -> Chính thức | E31: B_MB_QLDT | F31: =IF($E31="","",VLOOKUP($E31,'DS Dự án'!$B:$F,2,FALSE)) -> BI MB QLĐT | G31: =IF($E31="","",VLOOKUP($E31,'DS Dự án'!$B:$F,4,FALSE)) -> CongLC | H31: =IF($E31="","",VLOOKUP(E31,'DS Dự án'!$B:$F,5,0)) -> Đang thực hiện (Đã có hợp đồng) | I31: =A31&E31 -> phucldB_MB_QLDT | J31: 0.5 | K31: 0.5 | L31: 0.5 | M31: 0.5 | N31: 0.5 | O31: 0.5 | Q31: 0.5 | R31: 0.5 | S31: 0.5 | T31: 0.5 | U31: 0.5 | V31: 0.5 | W31: 0.5 | X31: 0.5 | Y31: 0.5 | Z31: 0.5 | AA31: 0.5 | AB31: 0.5 | AC31: 0.5 | AD31: 0.5 | AE31: 0.5 | AF31: 0.5 | AG31: 0.5 | AH31: 0.5 | AI31: 0.5
A32: conglc | B32: =IF(A32="","",VLOOKUP(A32,'DS Nhân viên'!B:C,2,FALSE)) -> Lê Chí Công | C32: =IF(A32="","",VLOOKUP(A32,'DS Nhân viên'!B:D,3,FALSE)) -> P.Kỹ thuật IBS | D32: =IF(A32="","",VLOOKUP(A32,'DS Nhân viên'!$B:$F,5,FALSE)) -> Chính thức | E32: B_MB_QLDT | F32: =IF($E32="","",VLOOKUP($E32,'DS Dự án'!$B:$F,2,FALSE)) -> BI MB QLĐT | G32: =IF($E32="","",VLOOKUP($E32,'DS Dự án'!$B:$F,4,FALSE)) -> CongLC | H32: =IF($E32="","",VLOOKUP(E32,'DS Dự án'!$B:$F,5,0)) -> Đang thực hiện (Đã có hợp đồng) | I32: =A32&E32 -> conglcB_MB_QLDT | J32: 0.2 | K32: 0.2 | L32: 0.2 | M32: 0.2 | N32: 0.1 | O32: 0.1 | Q32: 0.2 | R32: 0.2 | S32: 0.2 | T32: 0.2 | U32: 0.2 | V32: 0.2 | W32: 0.2 | X32: 0.2 | Y32: 0.2 | Z32: 0.2 | AA32: 0.2 | AB32: 0.2 | AC32: 0.2 | AD32: 0.2 | AE32: 0.2 | AF32: 0.2 | AG32: 0.2 | AH32: 0.2 | AI32: 0.2
A33: maint | B33: =IF(A33="","",VLOOKUP(A33,'DS Nhân viên'!B:C,2,FALSE)) -> Nguyễn Thanh Mai | C33: =IF(A33="","",VLOOKUP(A33,'DS Nhân viên'!B:D,3,FALSE)) -> P.Nghiệp vụ IBS | D33: =IF(A33="","",VLOOKUP(A33,'DS Nhân viên'!$B:$F,5,FALSE)) -> Chính thức | E33: B_MB_QLDT | F33: =IF($E33="","",VLOOKUP($E33,'DS Dự án'!$B:$F,2,FALSE)) -> BI MB QLĐT | G33: =IF($E33="","",VLOOKUP($E33,'DS Dự án'!$B:$F,4,FALSE)) -> CongLC | H33: =IF($E33="","",VLOOKUP(E33,'DS Dự án'!$B:$F,5,0)) -> Đang thực hiện (Đã có hợp đồng) | I33: =A33&E33 -> maintB_MB_QLDT | R33: 0.5 | S33: 0.5 | T33: 0.5 | U33: 0.5 | V33: 0.5 | W33: 0.5 | X33: 0.5 | Y33: 0.5 | Z33: 0.5 | AA33: 0.5 | AB33: 0.5 | AC33: 0.5 | AD33: 0.5 | AE33: 0.5 | AF33: 0.5 | AG33: 0.5 | AH33: 0.5 | AI33: 0.5
A34: tanhm | B34: =IF(A34="","",VLOOKUP(A34,'DS Nhân viên'!B:C,2,FALSE)) -> Hà Mạnh Tân | C34: =IF(A34="","",VLOOKUP(A34,'DS Nhân viên'!B:D,3,FALSE)) -> P.Nghiệp vụ IBS | D34: =IF(A34="","",VLOOKUP(A34,'DS Nhân viên'!$B:$F,5,FALSE)) -> Chính thức | E34: BD_TH0_01_00 | F34: =IF($E34="","",VLOOKUP($E34,'DS Dự án'!$B:$F,2,FALSE)) -> BI QLNL THADICO | G34: =IF($E34="","",VLOOKUP($E34,'DS Dự án'!$B:$F,4,FALSE)) -> AnhHT | H34: =IF($E34="","",VLOOKUP(E34,'DS Dự án'!$B:$F,5,0)) -> Đang thực hiện (Đã có hợp đồng) | I34: =A34&E34 -> tanhmBD_TH0_01_00
A35: tamtn | B35: =IF(A35="","",VLOOKUP(A35,'DS Nhân viên'!B:C,2,FALSE)) -> Trịnh Ngọc Tâm | C35: =IF(A35="","",VLOOKUP(A35,'DS Nhân viên'!B:D,3,FALSE)) -> P.Kỹ thuật IBS | D35: =IF(A35="","",VLOOKUP(A35,'DS Nhân viên'!$B:$F,5,FALSE)) -> Chính thức | E35: BD_TH0_01_00 | F35: =IF($E35="","",VLOOKUP($E35,'DS Dự án'!$B:$F,2,FALSE)) -> BI QLNL THADICO | G35: =IF($E35="","",VLOOKUP($E35,'DS Dự án'!$B:$F,4,FALSE)) -> AnhHT | H35: =IF($E35="","",VLOOKUP(E35,'DS Dự án'!$B:$F,5,0)) -> Đang thực hiện (Đã có hợp đồng) | I35: =A35&E35 -> tamtnBD_TH0_01_00
A36: huyenttt | B36: =IF(A36="","",VLOOKUP(A36,'DS Nhân viên'!B:C,2,FALSE)) -> Trần Thị Thanh Huyền | C36: =IF(A36="","",VLOOKUP(A36,'DS Nhân viên'!B:D,3,FALSE)) -> P.Nghiệp vụ IBS | D36: =IF(A36="","",VLOOKUP(A36,'DS Nhân viên'!$B:$F,5,FALSE)) -> Chính thức | E36: BD_TH0_01_00 | F36: =IF($E36="","",VLOOKUP($E36,'DS Dự án'!$B:$F,2,FALSE)) -> BI QLNL THADICO | G36: =IF($E36="","",VLOOKUP($E36,'DS Dự án'!$B:$F,4,FALSE)) -> AnhHT | H36: =IF($E36="","",VLOOKUP(E36,'DS Dự án'!$B:$F,5,0)) -> Đang thực hiện (Đã có hợp đồng) | I36: =A36&E36 -> huyentttBD_TH0_01_00 | J36: 0.2 | K36: 0.2 | L36: 0.2 | N36: 0.2 | O36: 0.2 | R36: 0.35 | S36: 0.3 | T36: 0.35 | U36: 0.3 | V36: 0.35 | W36: 0.15 | X36: 0.15 | Y36: 0.15 | Z36: 0.15 | AA36: 0.15 | AB36: 0.15 | AC36: 0.15 | AD36: 0.15 | AE36: 0.15 | AF36: 0.15 | AG36: 0.15 | AH36: 0.15 | AI36: 0.15
A37: anhht | B37: =IF(A37="","",VLOOKUP(A37,'DS Nhân viên'!B:C,2,FALSE)) -> Hoàng Tuấn Anh | C37: =IF(A37="","",VLOOKUP(A37,'DS Nhân viên'!B:D,3,FALSE)) -> P.Nghiệp vụ IBS | D37: =IF(A37="","",VLOOKUP(A37,'DS Nhân viên'!$B:$F,5,FALSE)) -> Chính thức | E37: BD_TH0_01_00 | F37: =IF($E37="","",VLOOKUP($E37,'DS Dự án'!$B:$F,2,FALSE)) -> BI QLNL THADICO | G37: =IF($E37="","",VLOOKUP($E37,'DS Dự án'!$B:$F,4,FALSE)) -> AnhHT | H37: =IF($E37="","",VLOOKUP(E37,'DS Dự án'!$B:$F,5,0)) -> Đang thực hiện (Đã có hợp đồng) | I37: =A37&E37 -> anhhtBD_TH0_01_00 | K37: 0.2 | L37: 0.1 | M37: 0.1 | N37: 0.1 | Q37: 0.15 | R37: 0.15 | S37: 0.15 | T37: 0.15 | U37: 0.15 | V37: 0.15
A38: trangth | B38: =IF(A38="","",VLOOKUP(A38,'DS Nhân viên'!B:C,2,FALSE)) -> Trần Huyền Trang | C38: =IF(B38="","",VLOOKUP(B38,'DS Nhân viên'!C:D,2,FALSE)) -> P.Nghiệp vụ IBS | D38: =IF(A38="","",VLOOKUP(A38,'DS Nhân viên'!$B:$F,5,FALSE)) -> Chính thức | E38: BD_BT0_01_00 | F38: =IF($E38="","",VLOOKUP($E38,'DS Dự án'!$B:$F,2,FALSE)) -> BI TK POWER BI BTMHH | G38: =IF($E38="","",VLOOKUP($E38,'DS Dự án'!$B:$F,4,FALSE)) -> AnhHT | H38: =IF($E38="","",VLOOKUP(E38,'DS Dự án'!$B:$F,5,0)) -> Bảo hành, Bảo trì | I38: =A38&E38 -> trangthBD_BT0_01_00 | J38: 0.7 | K38: 0.7
A39: anhht | B39: =IF(A39="","",VLOOKUP(A39,'DS Nhân viên'!B:C,2,FALSE)) -> Hoàng Tuấn Anh | C39: =IF(B39="","",VLOOKUP(B39,'DS Nhân viên'!C:D,2,FALSE)) -> P.Nghiệp vụ IBS | D39: =IF(A39="","",VLOOKUP(A39,'DS Nhân viên'!$B:$F,5,FALSE)) -> Chính thức | E39: BD_BT0_01_00 | F39: =IF($E39="","",VLOOKUP($E39,'DS Dự án'!$B:$F,2,FALSE)) -> BI TK POWER BI BTMHH | G39: =IF($E39="","",VLOOKUP($E39,'DS Dự án'!$B:$F,4,FALSE)) -> AnhHT | H39: =IF($E39="","",VLOOKUP(E39,'DS Dự án'!$B:$F,5,0)) -> Bảo hành, Bảo trì | I39: =A39&E39 -> anhhtBD_BT0_01_00 | J39: 0.6 | K39: 0.5 | L39: 0.1 | M39: 0.1
A40: tamtn | B40: =IF(A40="","",VLOOKUP(A40,'DS Nhân viên'!B:C,2,FALSE)) -> Trịnh Ngọc Tâm | C40: =IF(A40="","",VLOOKUP(A40,'DS Nhân viên'!B:D,3,FALSE)) -> P.Kỹ thuật IBS | D40: =IF(A40="","",VLOOKUP(A40,'DS Nhân viên'!$B:$F,5,FALSE)) -> Chính thức | E40: BD_BT0_01_00 | F40: =IF($E40="","",VLOOKUP($E40,'DS Dự án'!$B:$F,2,FALSE)) -> BI TK POWER BI BTMHH | G40: =IF($E40="","",VLOOKUP($E40,'DS Dự án'!$B:$F,4,FALSE)) -> AnhHT | H40: =IF($E40="","",VLOOKUP(E40,'DS Dự án'!$B:$F,5,0)) -> Bảo hành, Bảo trì | I40: =A40&E40 -> tamtnBD_BT0_01_00 | R40: 0.1 | S40: 0.1 | T40: 0.1 | U40: 0.1 | V40: 0.1 | W40: 0.1 | X40: 0.1 | Y40: 0.1 | Z40: 0.1 | AA40: 0.1 | AB40: 0.1 | AC40: 0.1 | AD40: 0.1 | AE40: 0.1 | AF40: 0.1 | AG40: 0.1 | AH40: 0.1 | AI40: 0.1
...

Sheet DS Nhân viên
A1: STT | B1: ID | C1: Họ và Tên | D1: Phòng Ban TT | E1: Nguồn lực | F1: Trạng thái nhân viên
A2: =IF(B2="","",MAX($A$1,A1)+1) -> 1 | B2: conglc | C2: Lê Chí Công | D2: P.Kỹ thuật IBS | E2: Senior | F2: Chính thức
A3: =IF(B3="","",MAX($A$1,A2)+1) -> 2 | B3: giangntt | C3: Nguyễn Thị Trà Giang | D3: P.Kỹ thuật IBS | E3: Senior | F3: Chính thức
A4: =IF(B4="","",MAX($A$1,A3)+1) -> 3 | B4: hieudt | C4: Đỗ Trung Hiếu | D4: P.Kỹ thuật IBS | E4: Experienced | F4: Học việc
A5: =IF(B5="","",MAX($A$1,A4)+1) -> 4 | B5: lamnv | C5: Nguyễn Việt Lâm | D5: P.Kỹ thuật IBS | E5: Experienced | F5: Học việc
A6: =IF(B6="","",MAX($A$1,A5)+1) -> 5 | B6: longlm | C6: Lê Minh Long | D6: P.Kỹ thuật IBS | E6: Assesed | F6: Học việc
A7: =IF(B7="","",MAX($A$1,A6)+1) -> 6 | B7: nhungnt2 | C7: Ngô Thị Nhung | D7: P.Kỹ thuật IBS | E7: Assesed | F7: Chính thức
A8: =IF(B8="","",MAX($A$1,A7)+1) -> 7 | B8: phucld | C8: Lê Đình Phúc | D8: P.Kỹ thuật IBS | E8: Assesed | F8: Chính thức
A9: =IF(B9="","",MAX($A$1,A8)+1) -> 8 | B9: tamtn | C9: Trịnh Ngọc Tâm | D9: P.Kỹ thuật IBS | E9: Assesed | F9: Chính thức
A10: =IF(B10="","",MAX($A$1,A9)+1) -> 9 | B10: anhht | C10: Hoàng Tuấn Anh | D10: P.Nghiệp vụ IBS | E10: Assesed | F10: Chính thức
A11: =IF(B11="","",MAX($A$1,A10)+1) -> 10 | B11: anhnht | C11: Nguyễn Hoàng Tuấn Anh | D11: P.Nghiệp vụ IBS | E11: Assesed | F11: Chính thức
A12: =IF(B12="","",MAX($A$1,A11)+1) -> 11 | B12: ngocdh | C12: Dương Hồng Ngọc | D12: P.Nghiệp vụ IBS | E12: Assesed | F12: Chính thức
A13: =IF(B13="","",MAX($A$1,A12)+1) -> 12 | B13: tanhm | C13: Hà Mạnh Tân | D13: P.Nghiệp vụ IBS | E13: Experienced | F13: Chính thức
... A27: =IF(B27="","",MAX($A$1,A26)+1) -> 26 | B27: hieunm | C27: Nguyễn Minh Hiếu | D27: P.Kỹ thuật IBS | E27: Assesed | F27: Thử việc
A28: =IF(B28="","",MAX($A$1,A27)+1)
A29: =IF(B29="","",MAX($A$1,A28)+1)
A30: =IF(B30="","",MAX($A$1,A29)+1)
A31: =IF(B31="","",MAX($A$1,A30)+1)
A32: =IF(B32="","",MAX($A$1,A31)+1)
A33: =IF(B33="","",MAX($A$1,A32)+1)
A34: =IF(B34="","",MAX($A$1,A33)+1)
A35: =IF(B35="","",MAX($A$1,A34)+1)
A36: =IF(B36="","",MAX($A$1,A35)+1)
A37: =IF(B37="","",MAX($A$1,A36)+1)
A38: =IF(B38="","",MAX($A$1,A37)+1)
A39: =IF(B39="","",MAX($A$1,A38)+1)
... A46: =IF(B46="","",MAX($A$1,A45)+1)

Sheet DS Dự án
A1: STT | B1: Mã DA | C1: Tên DA | D1: Mô tả DA | E1: PM | F1: Loại Dự án
A2: =IF(B2="","",MAX($A$1,A1)+1) -> 1 | B2: B_BAOTINMANHHAI | C2: B_BAOTINMANHHAI | D2: Triển khai Kho dữ liệu và Business Intelligence cho Bảo Tín Mạnh Hải | E2: AnhHT | F2: Đóng
A3: =IF(B3="","",MAX($A$1,A2)+1) -> 2 | B3: BD_ID0_01_00 | C3: BI DATA INDEVCO | D3: Triển khai và thiết kế hệ thống chuẩn hóa Master Data cho INDEVCO | E3: AnhHT | F3: Đang thực hiện (Đã có hợp đồng)
A4: =IF(B4="","",MAX($A$1,A3)+1) -> 3 | B4: BD_TH0_01_00 | C4: BI QLNL THADICO | D4: Phần mềm QL nguồn lực Thadico - Hạng mục công việc của TT IBS | E4: AnhHT | F4: Đang thực hiện (Đã có hợp đồng)
A5: =IF(B5="","",MAX($A$1,A4)+1) -> 4 | B5: BD_TH0_02_00 | C5: BI DWH THADICO | D5: Triển khai phần mềm Kho dữ liệu tập trung và phát triển các báo cáo quản trị chi phí giá thành các sản phẩm, dịch vụ cho THADICO | E5: AnhHT | F5: Tạm dừng
A6: =IF(B6="","",MAX($A$1,A5)+1) -> 5 | B6: BD_BW0_01_00 | C6: TK BI DWH BW SAO HOA | D6: Triển khai Kho dữ liệu tập trung và tự động hóa file Model | E6: AnhHT | F6: Đang thực hiện (Đã có hợp đồng)
A7: =IF(B7="","",MAX($A$1,A6)+1) -> 6 | B7: BB_VR1_02_00 | C7: BT BI DWH VCR NAM 2 | D7: Bảo trì VCR 2 | E7: AnhHT | F7: Bảo hành, Bảo trì
A8: =IF(B8="","",MAX($A$1,A7)+1) -> 7 | B8: BD_BT0_01_00 | C8: BI TK POWER BI BTMHH | D8: Triển khai chuyển đổi số dashboard từ Tableau sang POWER BI cho phòng Cung ứng Bảo Tín Mạnh Hải | E8: AnhHT | F8: Bảo hành, Bảo trì
A9: =IF(B9="","",MAX($A$1,A8)+1) -> 8 | B9: B_VNA_RPS | C9: B_VNA_RPS | D9: TK hệ thống phân tích hiệu quả đường bay (RPS) cho VNA | E9: AnhNHT | F9: Đang thực hiện (Đã có hợp đồng)
A10: =IF(B10="","",MAX($A$1,A9)+1) -> 9 | B10: BD_EN1_01_00 | C10: BI GENCO1 2025 | D10: Triển khai BI hệ thống hỗ trợ ra quyết định cho GENCO1 | E10: AnhNHT | F10: Đóng
A11: =IF(B11="","",MAX($A$1,A10)+1) -> 10 | B11: BD_EN2_01_00 | C11: BI EVNICT CMIS | D11: Thuê ngoài lập trình hàm và báo cáo CMIS cho EVN Chi nhánh tập đoàn điện lực Việt Nam | E11: AnhNHT | F11: Đóng
A12: =IF(B12="","",MAX($A$1,A11)+1) -> 11 | B12: BD_GE0_01_00 | C12: BI DWH GELEXIMCO | D12: Triển khai Kho dữ liệu và Business Intelligence cho Geleximco | E12: AnhNHT | F12: Đang thực hiện (Đã có hợp đồng)
A13: =IF(B13="","",MAX($A$1,A12)+1) -> 12 | B13: BD_EN4_01_00 | C13: BI EVN HCM GD2 | E13: AnhNHT | F13: Cơ hội
A14: =IF(B14="","",MAX($A$1,A13)+1) -> 13 | B14: POC_VIETTIN | C14: POC_VIETTIN | E14: AnhNHT | F14: Đóng
A15: =IF(B15="","",MAX($A$1,A14)+1) -> 14 | B15: BD_EN5_01_00 | C15: BI EVN SPC | E15: AnhNHT | F15: Cơ hội
A16: =IF(B16="","",MAX($A$1,A15)+1) -> 15 | B16: B_MB_AUTOMATION_QA_CNTT | C16: BI MB QA | D16: Xây dựng hệ thống báo cáo Automation QA cho khối CNTT của MB | E16: CongLC | F16: Đóng
A17: =IF(B17="","",MAX($A$1,A16)+1) -> 16 | B17: B_MB_QLDT | C17: BI MB QLĐT | D17: Xây dựng hệ thống báo cáo QLĐT cho khối CNTT của MB | E17: CongLC | F17: Đang thực hiện (Đã có hợp đồng)
A18: =IF(B18="","",MAX($A$1,A17)+1) -> 17 | B18: BD_TC0_01_00 | C18: MDM & DWH-BI THACO | D18: Xây dựng hệ thống quản lý Master Data, Kho dữ liệu và Báo cáo BI cho THACO | E18: HaiDL | F18: Cơ hội
A19: =IF(B19="","",MAX($A$1,A18)+1) -> 18 | B19: NB_CHAMCONG | C19: TK PM QLNL NB | D19: Triển khai phần mềm chấm công Quản lý nguồn lực nội bộ của iERP | E19: LamBH | F19: Đang thực hiện (Nội bộ)
A20: =IF(B20="","",MAX($A$1,A19)+1) -> 19 | B20: RD_OR0_01_00 | C20: PM CAN ORISTAR | D20: Triển khai phần mềm cân cho Oristar phần việc của Trung tâm NCPT | E20: LamBH | F20: Đang thực hiện (Đã có hợp đồng)
A21: =IF(B21="","",MAX($A$1,A20)+1) -> 20 | B21: RD_TH0_01_00 | C21: R&D QLNL THADICO | D21: Triển khai phần mềm hệ thống Quản lý nguồn lực cho Thadico phần việc của Trung tâm NCPT | E21: LamBH | F21: Đang thực hiện (Đã có hợp đồng)
A22: =IF(B22="","",MAX($A$1,A21)+1) -> 21 | B22: B_MB_ARCHIVE | C22: B_MB_ARCHIVE | E22: NgocDH | F22: Đang thực hiện (Đã có hợp đồng)
A23: =IF(B23="","",MAX($A$1,A22)+1) -> 22 | B23: HTNC | C23: HTNC | D23: Học tập nghiên cứu | E23: HaiDL | F23: Đang thực hiện (Nội bộ)
A24: =IF(B24="","",MAX($A$1,A23)+1) -> 23 | B24: HDC | C24: HDC | D24: Hoạt động chung | E24: HaiDL | F24: Đang thực hiện (Nội bộ)
A25: =IF(B25="","",MAX($A$1,A24)+1) -> 24 | B25: R | C25: R | D25: Nghỉ hưởng lương | E25: HaiDL | F25: Đang thực hiện (Nội bộ)
A26: =IF(B26="","",MAX($A$1,A25)+1) -> 25 | B26: QL | C26: QL | D26: QL trung tâm | E26: HaiDL | F26: Đang thực hiện (Nội bộ)
A27: =IF(B27="","",MAX($A$1,A26)+1) -> 26 | B27: Presale | C27: Presale | D27: Presale | E27: HaiDL | F27: Đang thực hiện (Nội bộ)
A28: =IF(B28="","",MAX($A$1,A27)+1) -> 27 | B28: CD_MB0_01_00 | C28: MB AUTO QA GD2 | D28: Xây dựng hệ thống báo cáo Automation QA cho khối CNTT của MB giai đoạn 2 | E28: NgocDH | F28: Đang thực hiện (Chưa có hợp đồng)
A29: =IF(B29="","",MAX($A$1,A28)+1) -> 28 | B29: BD_SU0_01_00 | C29: TU VAN SUITE CLOUD | D29: Tư vấn lĩnh vực thiết kế dữ liệu và kiến trúc Kho dữ liệu (Data Warehouse) phục vụ hệ thống Oracle NetSuite ERP, Oracle Netsuite Analytic Warehouse và các hệ thống liên quan cho Suite Cloud | E29: AnhHT | F29: Đang thực hiện (Chưa có hợp đồng)
A30: =IF(B30="","",MAX($A$1,A29)+1) -> 29 | B30: NB_NDI | C30: Vận hành công ty NDI | D30: Vận hành công ty NDI | E30: HaiDL | F30: Đang thực hiện (Nội bộ)
A31: =IF(B31="","",MAX($A$1,A30)+1) -> 30 | B31: B_TDA_GD2 | C31: DG2 TĐA | D31: Giai đoạn 2 Chiết khấu bán hàng Tôn Đông Á | E31: LamBH | F31: Cơ hội
A32: =IF(B32="","",MAX($A$1,A31)+1) -> 31 | B32: VAECO | C32: VAECO | D32: Tư vấn Datalake, DWH | E32: AnhNHT | F32: Cơ hội
A33: =IF(B33="","",MAX($A$1,A32)+1) -> 32 | B33: BD_VR1_01_00 | C33: Nâng cấp Ước KQKD | D33: Nâng cấp Ước KQKD cho TTTM | E33: AnhHT | F33: Đang thực hiện (Chưa có hợp đồng)
A34: =IF(B34="","",MAX($A$1,A33)+1) -> 33 | B34: B_CFC_AUTOMATION_XH | C34: Xuất hàng không dừng | D34: Xây dựng hệ thống xuất hàng không dừng cho Xi măng Chinfon | E34: LamBH | F34: Cơ hội
... A45: =IF(B45="","",MAX($A$1,A44)+1) -> 44 | B45: NB_AI_Onprem | C45: NB AI ONPREM | D45: Xây dựng thử nghiệm hệ thống Data-AI Onprem | E45: AnhHT | F45: Đang thực hiện (Nội bộ)
A46: =IF(B46="","",MAX($A$1,A45)+1)
A47: =IF(B47="","",MAX($A$1,A46)+1)
A48: =IF(B48="","",MAX($A$1,A47)+1)
A49: =IF(B49="","",MAX($A$1,A48)+1)
A50: =IF(B50="","",MAX($A$1,A49)+1)

Sheet Danh mục
A1: Trạng thái | C1: Định nghĩa | G1: Assesed
A2: Cơ hội | E2: Học việc | G2: Experienced
A3: Đang thực hiện (Nội bộ) | E3: Thử việc | G3: Senior
A4: Đang thực hiện (Chưa có hợp đồng) | E4: Thử việc
A5: Đang thực hiện (Đã có hợp đồng) | E5: Chính thức
A6: Tạm dừng | E6: Đã nghỉ việc
A7: Bảo hành, Bảo trì | C7: Đã hoàn tất nghiệm thu/Có hợp đồng bảo trì
A8: Đóng

Sheet TH_GCSX
A1: Trung tâm | B1: Họ và tên | C1: Level | D1: Năm | E1: Bình quân | F1: 1 | G1: 2 | H1: 3 | I1: 4 | J1: 5 | K1: 6 | L1: 7 | M1: 8 | N1: 9 | O1: 10 | P1: 11 | Q1: 12
A2: =VLOOKUP($B2,'DS Nhân viên'!$C:$D,2,0) -> P.Kỹ thuật IBS | B2: {=_xlfn.UNIQUE('Resource Plan'!B2:B88)} -> Trịnh Ngọc Tâm | C2: =A2&VLOOKUP($B2,'DS Nhân viên'!$C:$W,6,0) -> P.Kỹ thuật IBS | D2: 2025 | E2: =AVERAGE(F2:Q2) -> #REF! | F2: =SUMIF('Resource Plan'!$B:$B,$B2,'Resource Plan'!#REF!) -> #REF! | G2: =SUMIF('Resource Plan'!$B:$B,$B2,'Resource Plan'!#REF!) -> #REF! | H2: =SUMIF('Resource Plan'!$B:$B,$B2,'Resource Plan'!#REF!) -> #REF! | I2: =SUMIF('Resource Plan'!$B:$B,$B2,'Resource Plan'!#REF!) -> #REF! | J2: =SUMIF('Resource Plan'!$B:$B,$B2,'Resource Plan'!#REF!) -> #REF! | K2: =SUMIF('Resource Plan'!$B:$B,$B2,'Resource Plan'!#REF!) -> #REF! | L2: =SUMIF('Resource Plan'!$B:$B,$B2,'Resource Plan'!#REF!) -> #REF! | M2: =SUMIF('Resource Plan'!$B:$B,$B2,'Resource Plan'!#REF!) -> #REF! | ... Q2: =SUMIF('Resource Plan'!$B:$B,$B2,'Resource Plan'!#REF!) -> #REF!
A3: =VLOOKUP(B3,'DS Nhân viên'!$C:$D,2,0) -> P.Nghiệp vụ IBS | B3: Dương Hồng Ngọc | C3: =A3&VLOOKUP($B3,'DS Nhân viên'!$C:$W,6,0) -> P.Nghiệp vụ IBS | D3: 2025 | E3: =AVERAGE(F3:Q3) -> #REF! | F3: =SUMIF('Resource Plan'!$B:$B,$B3,'Resource Plan'!#REF!) -> #REF! | G3: =SUMIF('Resource Plan'!$B:$B,$B3,'Resource Plan'!#REF!) -> #REF! | H3: =SUMIF('Resource Plan'!$B:$B,$B3,'Resource Plan'!#REF!) -> #REF! | I3: =SUMIF('Resource Plan'!$B:$B,$B3,'Resource Plan'!#REF!) -> #REF! | J3: =SUMIF('Resource Plan'!$B:$B,$B3,'Resource Plan'!#REF!) -> #REF! | K3: =SUMIF('Resource Plan'!$B:$B,$B3,'Resource Plan'!#REF!) -> #REF! | L3: =SUMIF('Resource Plan'!$B:$B,$B3,'Resource Plan'!#REF!) -> #REF! | M3: =SUMIF('Resource Plan'!$B:$B,$B3,'Resource Plan'!#REF!) -> #REF! | ... Q3: =SUMIF('Resource Plan'!$B:$B,$B3,'Resource Plan'!#REF!) -> #REF!
A4: =VLOOKUP(B4,'DS Nhân viên'!$C:$D,2,0) -> P.Kỹ thuật IBS | B4: Lê Minh Long | C4: =A4&VLOOKUP($B4,'DS Nhân viên'!$C:$W,6,0) -> P.Kỹ thuật IBS | D4: 2025 | E4: =AVERAGE(F4:Q4) -> #REF! | F4: =SUMIF('Resource Plan'!$B:$B,$B4,'Resource Plan'!#REF!) -> #REF! | G4: =SUMIF('Resource Plan'!$B:$B,$B4,'Resource Plan'!#REF!) -> #REF! | H4: =SUMIF('Resource Plan'!$B:$B,$B4,'Resource Plan'!#REF!) -> #REF! | I4: =SUMIF('Resource Plan'!$B:$B,$B4,'Resource Plan'!#REF!) -> #REF! | J4: =SUMIF('Resource Plan'!$B:$B,$B4,'Resource Plan'!#REF!) -> #REF! | K4: =SUMIF('Resource Plan'!$B:$B,$B4,'Resource Plan'!#REF!) -> #REF! | L4: =SUMIF('Resource Plan'!$B:$B,$B4,'Resource Plan'!#REF!) -> #REF! | M4: =SUMIF('Resource Plan'!$B:$B,$B4,'Resource Plan'!#REF!) -> #REF! | ... Q4: =SUMIF('Resource Plan'!$B:$B,$B4,'Resource Plan'!#REF!) -> #REF!
A5: =VLOOKUP(B5,'DS Nhân viên'!$C:$D,2,0) -> P.Kỹ thuật IBS | B5: Lê Chí Công | C5: =A5&VLOOKUP($B5,'DS Nhân viên'!$C:$W,6,0) -> P.Kỹ thuật IBS | D5: 2025 | E5: =AVERAGE(F5:Q5) -> #REF! | F5: =SUMIF('Resource Plan'!$B:$B,$B5,'Resource Plan'!#REF!) -> #REF! | G5: =SUMIF('Resource Plan'!$B:$B,$B5,'Resource Plan'!#REF!) -> #REF! | H5: =SUMIF('Resource Plan'!$B:$B,$B5,'Resource Plan'!#REF!) -> #REF! | I5: =SUMIF('Resource Plan'!$B:$B,$B5,'Resource Plan'!#REF!) -> #REF! | J5: =SUMIF('Resource Plan'!$B:$B,$B5,'Resource Plan'!#REF!) -> #REF! | K5: =SUMIF('Resource Plan'!$B:$B,$B5,'Resource Plan'!#REF!) -> #REF! | L5: =SUMIF('Resource Plan'!$B:$B,$B5,'Resource Plan'!#REF!) -> #REF! | M5: =SUMIF('Resource Plan'!$B:$B,$B5,'Resource Plan'!#REF!) -> #REF! | ... Q5: =SUMIF('Resource Plan'!$B:$B,$B5,'Resource Plan'!#REF!) -> #REF!
A6: =VLOOKUP(B6,'DS Nhân viên'!$C:$D,2,0) -> P.Nghiệp vụ IBS | B6: Nguyễn Mạnh Thắng | C6: =A6&VLOOKUP($B6,'DS Nhân viên'!$C:$W,6,0) -> P.Nghiệp vụ IBS | D6: 2025 | E6: =AVERAGE(F6:Q6) -> #REF! | F6: =SUMIF('Resource Plan'!$B:$B,$B6,'Resource Plan'!#REF!) -> #REF! | G6: =SUMIF('Resource Plan'!$B:$B,$B6,'Resource Plan'!#REF!) -> #REF! | H6: =SUMIF('Resource Plan'!$B:$B,$B6,'Resource Plan'!#REF!) -> #REF! | I6: =SUMIF('Resource Plan'!$B:$B,$B6,'Resource Plan'!#REF!) -> #REF! | J6: =SUMIF('Resource Plan'!$B:$B,$B6,'Resource Plan'!#REF!) -> #REF! | K6: =SUMIF('Resource Plan'!$B:$B,$B6,'Resource Plan'!#REF!) -> #REF! | L6: =SUMIF('Resource Plan'!$B:$B,$B6,'Resource Plan'!#REF!) -> #REF! | M6: =SUMIF('Resource Plan'!$B:$B,$B6,'Resource Plan'!#REF!) -> #REF! | ... Q6: =SUMIF('Resource Plan'!$B:$B,$B6,'Resource Plan'!#REF!) -> #REF!
A7: =VLOOKUP(B7,'DS Nhân viên'!$C:$D,2,0) -> P.Kỹ thuật IBS | B7: Nguyễn Việt Lâm | C7: =A7&VLOOKUP($B7,'DS Nhân viên'!$C:$W,6,0) -> P.Kỹ thuật IBS | D7: 2025 | E7: =AVERAGE(F7:Q7) -> #REF! | F7: =SUMIF('Resource Plan'!$B:$B,$B7,'Resource Plan'!#REF!) -> #REF! | G7: =SUMIF('Resource Plan'!$B:$B,$B7,'Resource Plan'!#REF!) -> #REF! | H7: =SUMIF('Resource Plan'!$B:$B,$B7,'Resource Plan'!#REF!) -> #REF! | I7: =SUMIF('Resource Plan'!$B:$B,$B7,'Resource Plan'!#REF!) -> #REF! | J7: =SUMIF('Resource Plan'!$B:$B,$B7,'Resource Plan'!#REF!) -> #REF! | K7: =SUMIF('Resource Plan'!$B:$B,$B7,'Resource Plan'!#REF!) -> #REF! | L7: =SUMIF('Resource Plan'!$B:$B,$B7,'Resource Plan'!#REF!) -> #REF! | M7: =SUMIF('Resource Plan'!$B:$B,$B7,'Resource Plan'!#REF!) -> #REF! | ... Q7: =SUMIF('Resource Plan'!$B:$B,$B7,'Resource Plan'!#REF!) -> #REF!
A8: =VLOOKUP(B8,'DS Nhân viên'!$C:$D,2,0) -> P.Nghiệp vụ IBS | B8: Nguyễn Hoàng Tuấn Anh | C8: =A8&VLOOKUP($B8,'DS Nhân viên'!$C:$W,6,0) -> P.Nghiệp vụ IBS | D8: 2025 | E8: =AVERAGE(F8:Q8) -> #REF! | F8: =SUMIF('Resource Plan'!$B:$B,$B8,'Resource Plan'!#REF!) -> #REF! | G8: =SUMIF('Resource Plan'!$B:$B,$B8,'Resource Plan'!#REF!) -> #REF! | H8: =SUMIF('Resource Plan'!$B:$B,$B8,'Resource Plan'!#REF!) -> #REF! | I8: =SUMIF('Resource Plan'!$B:$B,$B8,'Resource Plan'!#REF!) -> #REF! | J8: =SUMIF('Resource Plan'!$B:$B,$B8,'Resource Plan'!#REF!) -> #REF! | K8: =SUMIF('Resource Plan'!$B:$B,$B8,'Resource Plan'!#REF!) -> #REF! | L8: =SUMIF('Resource Plan'!$B:$B,$B8,'Resource Plan'!#REF!) -> #REF! | M8: =SUMIF('Resource Plan'!$B:$B,$B8,'Resource Plan'!#REF!) -> #REF! | ... Q8: =SUMIF('Resource Plan'!$B:$B,$B8,'Resource Plan'!#REF!) -> #REF!
A9: =VLOOKUP(B9,'DS Nhân viên'!$C:$D,2,0) -> P.Nghiệp vụ IBS | B9: Hoàng Tuấn Anh | C9: =A9&VLOOKUP($B9,'DS Nhân viên'!$C:$W,6,0) -> P.Nghiệp vụ IBS | D9: 2025 | E9: =AVERAGE(F9:Q9) -> #REF! | F9: =SUMIF('Resource Plan'!$B:$B,$B9,'Resource Plan'!#REF!) -> #REF! | G9: =SUMIF('Resource Plan'!$B:$B,$B9,'Resource Plan'!#REF!) -> #REF! | H9: =SUMIF('Resource Plan'!$B:$B,$B9,'Resource Plan'!#REF!) -> #REF! | I9: =SUMIF('Resource Plan'!$B:$B,$B9,'Resource Plan'!#REF!) -> #REF! | J9: =SUMIF('Resource Plan'!$B:$B,$B9,'Resource Plan'!#REF!) -> #REF! | K9: =SUMIF('Resource Plan'!$B:$B,$B9,'Resource Plan'!#REF!) -> #REF! | L9: =SUMIF('Resource Plan'!$B:$B,$B9,'Resource Plan'!#REF!) -> #REF! | M9: =SUMIF('Resource Plan'!$B:$B,$B9,'Resource Plan'!#REF!) -> #REF! | ... Q9: =SUMIF('Resource Plan'!$B:$B,$B9,'Resource Plan'!#REF!) -> #REF!
A10: =VLOOKUP(B10,'DS Nhân viên'!$C:$D,2,0) -> P.Kỹ thuật IBS | B10: Ngô Thị Nhung | C10: =A10&VLOOKUP($B10,'DS Nhân viên'!$C:$W,6,0) -> P.Kỹ thuật IBS | D10: 2025 | E10: =AVERAGE(F10:Q10) -> #REF! | F10: =SUMIF('Resource Plan'!$B:$B,$B10,'Resource Plan'!#REF!) -> #REF! | G10: =SUMIF('Resource Plan'!$B:$B,$B10,'Resource Plan'!#REF!) -> #REF! | H10: =SUMIF('Resource Plan'!$B:$B,$B10,'Resource Plan'!#REF!) -> #REF! | I10: =SUMIF('Resource Plan'!$B:$B,$B10,'Resource Plan'!#REF!) -> #REF! | J10: =SUMIF('Resource Plan'!$B:$B,$B10,'Resource Plan'!#REF!) -> #REF! | K10: =SUMIF('Resource Plan'!$B:$B,$B10,'Resource Plan'!#REF!) -> #REF! | L10: =SUMIF('Resource Plan'!$B:$B,$B10,'Resource Plan'!#REF!) -> #REF! | M10: =SUMIF('Resource Plan'!$B:$B,$B10,'Resource Plan'!#REF!) -> #REF! | ... Q10: =SUMIF('Resource Plan'!$B:$B,$B10,'Resource Plan'!#REF!) -> #REF!
A11: =VLOOKUP(B11,'DS Nhân viên'!$C:$D,2,0) -> P.Nghiệp vụ IBS | B11: Đinh Đức Minh | C11: =A11&VLOOKUP($B11,'DS Nhân viên'!$C:$W,6,0) -> P.Nghiệp vụ IBS | D11: 2025 | E11: =AVERAGE(F11:Q11) -> #REF! | F11: =SUMIF('Resource Plan'!$B:$B,$B11,'Resource Plan'!#REF!) -> #REF! | G11: =SUMIF('Resource Plan'!$B:$B,$B11,'Resource Plan'!#REF!) -> #REF! | H11: =SUMIF('Resource Plan'!$B:$B,$B11,'Resource Plan'!#REF!) -> #REF! | I11: =SUMIF('Resource Plan'!$B:$B,$B11,'Resource Plan'!#REF!) -> #REF! | J11: =SUMIF('Resource Plan'!$B:$B,$B11,'Resource Plan'!#REF!) -> #REF! | K11: =SUMIF('Resource Plan'!$B:$B,$B11,'Resource Plan'!#REF!) -> #REF! | L11: =SUMIF('Resource Plan'!$B:$B,$B11,'Resource Plan'!#REF!) -> #REF! | M11: =SUMIF('Resource Plan'!$B:$B,$B11,'Resource Plan'!#REF!) -> #REF! | ... Q11: =SUMIF('Resource Plan'!$B:$B,$B11,'Resource Plan'!#REF!) -> #REF!
A12: =VLOOKUP(B12,'DS Nhân viên'!$C:$D,2,0) -> P.Nghiệp vụ IBS | B12: Nguyễn Thanh Mai | C12: =A12&VLOOKUP($B12,'DS Nhân viên'!$C:$W,6,0) -> P.Nghiệp vụ IBS | D12: 2025 | E12: =AVERAGE(F12:Q12) -> #REF! | F12: =SUMIF('Resource Plan'!$B:$B,$B12,'Resource Plan'!#REF!) -> #REF! | G12: =SUMIF('Resource Plan'!$B:$B,$B12,'Resource Plan'!#REF!) -> #REF! | H12: =SUMIF('Resource Plan'!$B:$B,$B12,'Resource Plan'!#REF!) -> #REF! | I12: =SUMIF('Resource Plan'!$B:$B,$B12,'Resource Plan'!#REF!) -> #REF! | J12: =SUMIF('Resource Plan'!$B:$B,$B12,'Resource Plan'!#REF!) -> #REF! | K12: =SUMIF('Resource Plan'!$B:$B,$B12,'Resource Plan'!#REF!) -> #REF! | L12: =SUMIF('Resource Plan'!$B:$B,$B12,'Resource Plan'!#REF!) -> #REF! | M12: =SUMIF('Resource Plan'!$B:$B,$B12,'Resource Plan'!#REF!) -> #REF! | ... Q12: =SUMIF('Resource Plan'!$B:$B,$B12,'Resource Plan'!#REF!) -> #REF!
A13: =VLOOKUP(B13,'DS Nhân viên'!$C:$D,2,0) -> P.Kỹ thuật IBS | B13: Đỗ Trung Hiếu | C13: =A13&VLOOKUP($B13,'DS Nhân viên'!$C:$W,6,0) -> P.Kỹ thuật IBS | D13: 2025 | E13: =AVERAGE(F13:Q13) -> #REF! | F13: =SUMIF('Resource Plan'!$B:$B,$B13,'Resource Plan'!#REF!) -> #REF! | G13: =SUMIF('Resource Plan'!$B:$B,$B13,'Resource Plan'!#REF!) -> #REF! | H13: =SUMIF('Resource Plan'!$B:$B,$B13,'Resource Plan'!#REF!) -> #REF! | I13: =SUMIF('Resource Plan'!$B:$B,$B13,'Resource Plan'!#REF!) -> #REF! | J13: =SUMIF('Resource Plan'!$B:$B,$B13,'Resource Plan'!#REF!) -> #REF! | K13: =SUMIF('Resource Plan'!$B:$B,$B13,'Resource Plan'!#REF!) -> #REF! | L13: =SUMIF('Resource Plan'!$B:$B,$B13,'Resource Plan'!#REF!) -> #REF! | M13: =SUMIF('Resource Plan'!$B:$B,$B13,'Resource Plan'!#REF!) -> #REF! | ... Q13: =SUMIF('Resource Plan'!$B:$B,$B13,'Resource Plan'!#REF!) -> #REF!
A14: =VLOOKUP(B14,'DS Nhân viên'!$C:$D,2,0) -> P.Kỹ thuật IBS | B14: Nguyễn Minh Hiếu | C14: =A14&VLOOKUP($B14,'DS Nhân viên'!$C:$W,6,0) -> P.Kỹ thuật IBS | D14: 2025 | E14: =AVERAGE(F14:Q14) -> #REF! | F14: =SUMIF('Resource Plan'!$B:$B,$B14,'Resource Plan'!#REF!) -> #REF! | G14: =SUMIF('Resource Plan'!$B:$B,$B14,'Resource Plan'!#REF!) -> #REF! | H14: =SUMIF('Resource Plan'!$B:$B,$B14,'Resource Plan'!#REF!) -> #REF! | I14: =SUMIF('Resource Plan'!$B:$B,$B14,'Resource Plan'!#REF!) -> #REF! | J14: =SUMIF('Resource Plan'!$B:$B,$B14,'Resource Plan'!#REF!) -> #REF! | K14: =SUMIF('Resource Plan'!$B:$B,$B14,'Resource Plan'!#REF!) -> #REF! | L14: =SUMIF('Resource Plan'!$B:$B,$B14,'Resource Plan'!#REF!) -> #REF! | M14: =SUMIF('Resource Plan'!$B:$B,$B14,'Resource Plan'!#REF!) -> #REF! | ... Q14: =SUMIF('Resource Plan'!$B:$B,$B14,'Resource Plan'!#REF!) -> #REF!
... A17: =VLOOKUP(B17,'DS Nhân viên'!$C:$D,2,0) -> P.Nghiệp vụ IBS | B17: Trần Thị Thanh Huyền | C17: =A17&VLOOKUP($B17,'DS Nhân viên'!$C:$W,6,0) -> P.Nghiệp vụ IBS | D17: 2025 | E17: =AVERAGE(F17:Q17) -> #REF! | F17: =SUMIF('Resource Plan'!$B:$B,$B17,'Resource Plan'!#REF!) -> #REF! | G17: =SUMIF('Resource Plan'!$B:$B,$B17,'Resource Plan'!#REF!) -> #REF! | H17: =SUMIF('Resource Plan'!$B:$B,$B17,'Resource Plan'!#REF!) -> #REF! | I17: =SUMIF('Resource Plan'!$B:$B,$B17,'Resource Plan'!#REF!) -> #REF! | J17: =SUMIF('Resource Plan'!$B:$B,$B17,'Resource Plan'!#REF!) -> #REF! | K17: =SUMIF('Resource Plan'!$B:$B,$B17,'Resource Plan'!#REF!) -> #REF! | L17: =SUMIF('Resource Plan'!$B:$B,$B17,'Resource Plan'!#REF!) -> #REF! | M17: =SUMIF('Resource Plan'!$B:$B,$B17,'Resource Plan'!#REF!) -> #REF! | ... Q17: =SUMIF('Resource Plan'!$B:$B,$B17,'Resource Plan'!#REF!) -> #REF!
B18: Trần Huyền Trang
B19: Lê Đình Phúc
B20: Nghiêm Thanh Tùng
B21: Nguyễn Văn Diên
B22: Nguyễn Khắc Mạnh
B23: Bùi Hữu Lâm
B24: Phí Quang Vinh
B25: Vương Duy Long
B26: Nguyễn Thị Trà Giang
B27: Nguyễn Anh Đức
